Workbook

Sheet 使い方
A1: 弥生販売 仕入伝票 インポート用CSV たたき台
A3: ■ このファイルについて
A4: 元テンプレート「弥生販売 仕入伝票 インポート用データ作成テンプレート」を元に、必須・推奨項目のうち本当に人が判断しないと決まらない項目だけを「入力シート」に入力すれば、残りの41項目（伝票区分・端数処理設定・行番号・金額・消費税明細行など）を自動計算し、43列すべて（見出し行なし）の「CSV出力」シートを自動生成するたたき台です。
A6: ■ シート構成
A7: ・商品マスタ … 商品コードごとの商品名/単位/課税区分/数量小数桁/単価小数桁/原価の対応表。サンプル5商品のみ登録済み。ご自身の商品台帳の内容に置き換え・追記してください。
A8: ・入力シート … 実際に入力するシート。黄色い列だけ入力すればOKです。
A9: ・CSV出力 … 43列すべてを自動計算した最終データ（見出し行なし）。このシートの内容をコピーしてCSVとして保存します。
A11: ■ 入力手順
A12: ① 「商品マスタ」シートに自社の商品コード・商品名・単位・課税区分・数量小数桁・単価小数桁（・原価）を追記/修正する。
A13: ② 「入力シート」B2セルに、この回でインポートする最初の伝票番号（数字のみ、例:95）を入力する。
A14: ③ 「入力シート」の5行目以降、明細行を1行ずつ入力する。入力するのは【伝票日付・仕入先コード・仕入先名称・商品コード・数量・単価】の必須項目のみ。課税区分・明細区分・備考は空欄でも構いません（空欄なら自動判定/自動設定されます）。
A15: ④ 同じ「伝票日付」×「仕入先コード」が連続する行は、自動的に同じ1枚の伝票（同じ伝票番号）としてまとめられます。日付か仕入先コードが変わった時点で、自動的に次の伝票番号が採番されます。1行ずつ順番に入力していくだけで、伝票のグルーピングと行番号（明細の連番）はすべて自動計算されます。
... A27: ・入力シートは200行分（最大200明細行）まで対応しています。不足する場合はご相談ください。

Sheet 商品マスタ
A1: 商品マスタ（商品コード→商品名・単位・課税区分等の対応表）
A2: 課税区分: 13=通常課税10% / 30=軽減税率8% / 0=対象外。数量小数桁・単価小数桁は0〜4。
A4: 商品コード | B4: 商品名 | C4: 単位 | D4: 課税区分 | E4: 数量小数桁 | F4: 単価小数桁 | G4: 原価
A5: 1 | B5: 鉢マグロプレートA | C5: kg | D5: 30 | E5: 1 | F5: 1 | G5: 0
A6: 2 | B6: 黄肌鮪プレートA | C6: kg | D6: 30 | E6: 1 | F6: 1 | G6: 0
A7: 3 | B7: 黄肌鮪プレートB | C7: kg | D7: 30 | E7: 1 | F7: 1 | G7: 0
A8: 9 | B8: 畜養本鮪腹1 | C8: kg | D8: 30 | E8: 1 | F8: 1 | G8: 0
A9: 47 | B9: 鮪尾身 | C9: kg | D9: 30 | E9: 1 | F9: 1 | G9: 0

Sheet 入力シート
A1: 入力シート（必須項目だけ入力してください／黄色い列が入力欄、グレーの列は自動計算）
A2: 開始伝票番号: | B2: 90 | C2: ← この回でインポートする最初の伝票番号（数字のみ）。以降は日付・仕入先コードの変化に応じて自動的に+1されます。
A3: ↓ 以下2行（5〜6行目）は入力例です。同じ日付・仕入先コードの行は自動で同じ伝票にまとまることを確認できます。実データを入力する際はこの2行を書き換えてください。
A4: 伝票日付(必須) | B4: 仕入先コード(必須) | C4: 仕入先名称(推奨) | D4: 商品コード(必須) | E4: 数量(必須) | F4: 単価(必須) | G4: 明細区分 (空欄=通常/2=返品/3=値引/4=諸経費) | H4: 課税区分 (空欄=商品マスタから自動取得) | I4: 備考(任意) | J4: 商品名(自動) | K4: 単位(自動) | L4: 適用課税区分(自動) | M4: 数量小数桁(自動) | N4: 単価小数桁(自動) | O4: 金額(自動) | P4: 税抜額(自動) | Q4: =$B$2-1 -> 89 | R4: 行番号(自動) | S4: 伝票先頭フラグ(内部用) | T4: 伝票先頭連番(内部用) | U4: 原価(自動)
A5: 46238 | B5: 50 | C5: 株式会社オリエンタルフーズ | D5: 2 | E5: 1000 | F5: 2700 | J5: =IF($D5="","",IFERROR(VLOOKUP($D5,商品マスタ!$A$5:$G$1000,2,FALSE()),"※商品マスタ未登録")) -> 黄肌鮪プレートA | K5: =IF($D5="","",IFERROR(VLOOKUP($D5,商品マスタ!$A$5:$G$1000,3,FALSE()),"")) -> kg | L5: =IF($D5="","",IF($H5<>"",$H5,IFERROR(VLOOKUP($D5,商品マスタ!$A$5:$G$1000,4,FALSE()),""))) -> 30 | M5: =IF($D5="","",IFERROR(VLOOKUP($D5,商品マスタ!$A$5:$G$1000,5,FALSE()),0)) -> 1 | N5: =IF($D5="","",IFERROR(VLOOKUP($D5,商品マスタ!$A$5:$G$1000,6,FALSE()),0)) -> 1 | O5: =IF($D5="","",ROUND($E5*$F5,0)) -> 2700000 | P5: =IF($D5="","",$O5) -> 2700000 | Q5: =IF($A5="","",IF($S5=1,$Q4+1,$Q4)) -> 90 | R5: =IF($A5="","",IF($Q5=$Q4,$R4+1,1)) -> 1 | S5: =IF($A5="","",IF(AND($A5=$A4,$B5=$B4),0,1)) -> 1 | T5: =IF($A5="","",IF($S5=1,COUNTIF($S$5:$S5,1),"")) -> 1 | U5: =IF($D5="","",IFERROR(VLOOKUP($D5,商品マスタ!$A$5:$G$1000,7,FALSE()),0)) -> 0
A6: 46238 | B6: 50 | C6: 株式会社オリエンタルフーズ | D6: 3 | E6: 1000 | F6: 2450 | J6: =IF($D6="","",IFERROR(VLOOKUP($D6,商品マスタ!$A$5:$G$1000,2,FALSE()),"※商品マスタ未登録")) -> 黄肌鮪プレートB | K6: =IF($D6="","",IFERROR(VLOOKUP($D6,商品マスタ!$A$5:$G$1000,3,FALSE()),"")) -> kg | L6: =IF($D6="","",IF($H6<>"",$H6,IFERROR(VLOOKUP($D6,商品マスタ!$A$5:$G$1000,4,FALSE()),""))) -> 30 | M6: =IF($D6="","",IFERROR(VLOOKUP($D6,商品マスタ!$A$5:$G$1000,5,FALSE()),0)) -> 1 | N6: =IF($D6="","",IFERROR(VLOOKUP($D6,商品マスタ!$A$5:$G$1000,6,FALSE()),0)) -> 1 | O6: =IF($D6="","",ROUND($E6*$F6,0)) -> 2450000 | P6: =IF($D6="","",$O6) -> 2450000 | Q6: =IF($A6="","",IF($S6=1,$Q5+1,$Q5)) -> 90 | R6: =IF($A6="","",IF($Q6=$Q5,$R5+1,1)) -> 2 | S6: =IF($A6="","",IF(AND($A6=$A5,$B6=$B5),0,1)) -> 0 | T6: =IF($A6="","",IF($S6=1,COUNTIF($S$5:$S6,1),"")) | U6: =IF($D6="","",IFERROR(VLOOKUP($D6,商品マスタ!$A$5:$G$1000,7,FALSE()),0)) -> 0
J7: =IF($D7="","",IFERROR(VLOOKUP($D7,商品マスタ!$A$5:$G$1000,2,FALSE()),"※商品マスタ未登録")) | K7: =IF($D7="","",IFERROR(VLOOKUP($D7,商品マスタ!$A$5:$G$1000,3,FALSE()),"")) | L7: =IF($D7="","",IF($H7<>"",$H7,IFERROR(VLOOKUP($D7,商品マスタ!$A$5:$G$1000,4,FALSE()),""))) | M7: =IF($D7="","",IFERROR(VLOOKUP($D7,商品マスタ!$A$5:$G$1000,5,FALSE()),0)) | N7: =IF($D7="","",IFERROR(VLOOKUP($D7,商品マスタ!$A$5:$G$1000,6,FALSE()),0)) | O7: =IF($D7="","",ROUND($E7*$F7,0)) | P7: =IF($D7="","",$O7) | Q7: =IF($A7="","",IF($S7=1,$Q6+1,$Q6)) | R7: =IF($A7="","",IF($Q7=$Q6,$R6+1,1)) | S7: =IF($A7="","",IF(AND($A7=$A6,$B7=$B6),0,1)) | T7: =IF($A7="","",IF($S7=1,COUNTIF($S$5:$S7,1),"")) | U7: =IF($D7="","",IFERROR(VLOOKUP($D7,商品マスタ!$A$5:$G$1000,7,FALSE()),0))
J8: =IF($D8="","",IFERROR(VLOOKUP($D8,商品マスタ!$A$5:$G$1000,2,FALSE()),"※商品マスタ未登録")) | K8: =IF($D8="","",IFERROR(VLOOKUP($D8,商品マスタ!$A$5:$G$1000,3,FALSE()),"")) | L8: =IF($D8="","",IF($H8<>"",$H8,IFERROR(VLOOKUP($D8,商品マスタ!$A$5:$G$1000,4,FALSE()),""))) | M8: =IF($D8="","",IFERROR(VLOOKUP($D8,商品マスタ!$A$5:$G$1000,5,FALSE()),0)) | N8: =IF($D8="","",IFERROR(VLOOKUP($D8,商品マスタ!$A$5:$G$1000,6,FALSE()),0)) | O8: =IF($D8="","",ROUND($E8*$F8,0)) | P8: =IF($D8="","",$O8) | Q8: =IF($A8="","",IF($S8=1,$Q7+1,$Q7)) | R8: =IF($A8="","",IF($Q8=$Q7,$R7+1,1)) | S8: =IF($A8="","",IF(AND($A8=$A7,$B8=$B7),0,1)) | T8: =IF($A8="","",IF($S8=1,COUNTIF($S$5:$S8,1),"")) | U8: =IF($D8="","",IFERROR(VLOOKUP($D8,商品マスタ!$A$5:$G$1000,7,FALSE()),0))
J9: =IF($D9="","",IFERROR(VLOOKUP($D9,商品マスタ!$A$5:$G$1000,2,FALSE()),"※商品マスタ未登録")) | K9: =IF($D9="","",IFERROR(VLOOKUP($D9,商品マスタ!$A$5:$G$1000,3,FALSE()),"")) | L9: =IF($D9="","",IF($H9<>"",$H9,IFERROR(VLOOKUP($D9,商品マスタ!$A$5:$G$1000,4,FALSE()),""))) | M9: =IF($D9="","",IFERROR(VLOOKUP($D9,商品マスタ!$A$5:$G$1000,5,FALSE()),0)) | N9: =IF($D9="","",IFERROR(VLOOKUP($D9,商品マスタ!$A$5:$G$1000,6,FALSE()),0)) | O9: =IF($D9="","",ROUND($E9*$F9,0)) | P9: =IF($D9="","",$O9) | Q9: =IF($A9="","",IF($S9=1,$Q8+1,$Q8)) | R9: =IF($A9="","",IF($Q9=$Q8,$R8+1,1)) | S9: =IF($A9="","",IF(AND($A9=$A8,$B9=$B8),0,1)) | T9: =IF($A9="","",IF($S9=1,COUNTIF($S$5:$S9,1),"")) | U9: =IF($D9="","",IFERROR(VLOOKUP($D9,商品マスタ!$A$5:$G$1000,7,FALSE()),0))
J10: =IF($D10="","",IFERROR(VLOOKUP($D10,商品マスタ!$A$5:$G$1000,2,FALSE()),"※商品マスタ未登録")) | K10: =IF($D10="","",IFERROR(VLOOKUP($D10,商品マスタ!$A$5:$G$1000,3,FALSE()),"")) | L10: =IF($D10="","",IF($H10<>"",$H10,IFERROR(VLOOKUP($D10,商品マスタ!$A$5:$G$1000,4,FALSE()),""))) | M10: =IF($D10="","",IFERROR(VLOOKUP($D10,商品マスタ!$A$5:$G$1000,5,FALSE()),0)) | N10: =IF($D10="","",IFERROR(VLOOKUP($D10,商品マスタ!$A$5:$G$1000,6,FALSE()),0)) | O10: =IF($D10="","",ROUND($E10*$F10,0)) | P10: =IF($D10="","",$O10) | Q10: =IF($A10="","",IF($S10=1,$Q9+1,$Q9)) | R10: =IF($A10="","",IF($Q10=$Q9,$R9+1,1)) | S10: =IF($A10="","",IF(AND($A10=$A9,$B10=$B9),0,1)) | T10: =IF($A10="","",IF($S10=1,COUNTIF($S$5:$S10,1),"")) | U10: =IF($D10="","",IFERROR(VLOOKUP($D10,商品マスタ!$A$5:$G$1000,7,FALSE()),0))
J11: =IF($D11="","",IFERROR(VLOOKUP($D11,商品マスタ!$A$5:$G$1000,2,FALSE()),"※商品マスタ未登録")) | K11: =IF($D11="","",IFERROR(VLOOKUP($D11,商品マスタ!$A$5:$G$1000,3,FALSE()),"")) | L11: =IF($D11="","",IF($H11<>"",$H11,IFERROR(VLOOKUP($D11,商品マスタ!$A$5:$G$1000,4,FALSE()),""))) | M11: =IF($D11="","",IFERROR(VLOOKUP($D11,商品マスタ!$A$5:$G$1000,5,FALSE()),0)) | N11: =IF($D11="","",IFERROR(VLOOKUP($D11,商品マスタ!$A$5:$G$1000,6,FALSE()),0)) | O11: =IF($D11="","",ROUND($E11*$F11,0)) | P11: =IF($D11="","",$O11) | Q11: =IF($A11="","",IF($S11=1,$Q10+1,$Q10)) | R11: =IF($A11="","",IF($Q11=$Q10,$R10+1,1)) | S11: =IF($A11="","",IF(AND($A11=$A10,$B11=$B10),0,1)) | T11: =IF($A11="","",IF($S11=1,COUNTIF($S$5:$S11,1),"")) | U11: =IF($D11="","",IFERROR(VLOOKUP($D11,商品マスタ!$A$5:$G$1000,7,FALSE()),0))
J12: =IF($D12="","",IFERROR(VLOOKUP($D12,商品マスタ!$A$5:$G$1000,2,FALSE()),"※商品マスタ未登録")) | K12: =IF($D12="","",IFERROR(VLOOKUP($D12,商品マスタ!$A$5:$G$1000,3,FALSE()),"")) | L12: =IF($D12="","",IF($H12<>"",$H12,IFERROR(VLOOKUP($D12,商品マスタ!$A$5:$G$1000,4,FALSE()),""))) | M12: =IF($D12="","",IFERROR(VLOOKUP($D12,商品マスタ!$A$5:$G$1000,5,FALSE()),0)) | N12: =IF($D12="","",IFERROR(VLOOKUP($D12,商品マスタ!$A$5:$G$1000,6,FALSE()),0)) | O12: =IF($D12="","",ROUND($E12*$F12,0)) | P12: =IF($D12="","",$O12) | Q12: =IF($A12="","",IF($S12=1,$Q11+1,$Q11)) | R12: =IF($A12="","",IF($Q12=$Q11,$R11+1,1)) | S12: =IF($A12="","",IF(AND($A12=$A11,$B12=$B11),0,1)) | T12: =IF($A12="","",IF($S12=1,COUNTIF($S$5:$S12,1),"")) | U12: =IF($D12="","",IFERROR(VLOOKUP($D12,商品マスタ!$A$5:$G$1000,7,FALSE()),0))
J13: =IF($D13="","",IFERROR(VLOOKUP($D13,商品マスタ!$A$5:$G$1000,2,FALSE()),"※商品マスタ未登録")) | K13: =IF($D13="","",IFERROR(VLOOKUP($D13,商品マスタ!$A$5:$G$1000,3,FALSE()),"")) | L13: =IF($D13="","",IF($H13<>"",$H13,IFERROR(VLOOKUP($D13,商品マスタ!$A$5:$G$1000,4,FALSE()),""))) | M13: =IF($D13="","",IFERROR(VLOOKUP($D13,商品マスタ!$A$5:$G$1000,5,FALSE()),0)) | N13: =IF($D13="","",IFERROR(VLOOKUP($D13,商品マスタ!$A$5:$G$1000,6,FALSE()),0)) | O13: =IF($D13="","",ROUND($E13*$F13,0)) | P13: =IF($D13="","",$O13) | Q13: =IF($A13="","",IF($S13=1,$Q12+1,$Q12)) | R13: =IF($A13="","",IF($Q13=$Q12,$R12+1,1)) | S13: =IF($A13="","",IF(AND($A13=$A12,$B13=$B12),0,1)) | T13: =IF($A13="","",IF($S13=1,COUNTIF($S$5:$S13,1),"")) | U13: =IF($D13="","",IFERROR(VLOOKUP($D13,商品マスタ!$A$5:$G$1000,7,FALSE()),0))
J14: =IF($D14="","",IFERROR(VLOOKUP($D14,商品マスタ!$A$5:$G$1000,2,FALSE()),"※商品マスタ未登録")) | K14: =IF($D14="","",IFERROR(VLOOKUP($D14,商品マスタ!$A$5:$G$1000,3,FALSE()),"")) | L14: =IF($D14="","",IF($H14<>"",$H14,IFERROR(VLOOKUP($D14,商品マスタ!$A$5:$G$1000,4,FALSE()),""))) | M14: =IF($D14="","",IFERROR(VLOOKUP($D14,商品マスタ!$A$5:$G$1000,5,FALSE()),0)) | N14: =IF($D14="","",IFERROR(VLOOKUP($D14,商品マスタ!$A$5:$G$1000,6,FALSE()),0)) | O14: =IF($D14="","",ROUND($E14*$F14,0)) | P14: =IF($D14="","",$O14) | Q14: =IF($A14="","",IF($S14=1,$Q13+1,$Q13)) | R14: =IF($A14="","",IF($Q14=$Q13,$R13+1,1)) | S14: =IF($A14="","",IF(AND($A14=$A13,$B14=$B13),0,1)) | T14: =IF($A14="","",IF($S14=1,COUNTIF($S$5:$S14,1),"")) | U14: =IF($D14="","",IFERROR(VLOOKUP($D14,商品マスタ!$A$5:$G$1000,7,FALSE()),0))
J15: =IF($D15="","",IFERROR(VLOOKUP($D15,商品マスタ!$A$5:$G$1000,2,FALSE()),"※商品マスタ未登録")) | K15: =IF($D15="","",IFERROR(VLOOKUP($D15,商品マスタ!$A$5:$G$1000,3,FALSE()),"")) | L15: =IF($D15="","",IF($H15<>"",$H15,IFERROR(VLOOKUP($D15,商品マスタ!$A$5:$G$1000,4,FALSE()),""))) | M15: =IF($D15="","",IFERROR(VLOOKUP($D15,商品マスタ!$A$5:$G$1000,5,FALSE()),0)) | N15: =IF($D15="","",IFERROR(VLOOKUP($D15,商品マスタ!$A$5:$G$1000,6,FALSE()),0)) | O15: =IF($D15="","",ROUND($E15*$F15,0)) | P15: =IF($D15="","",$O15) | Q15: =IF($A15="","",IF($S15=1,$Q14+1,$Q14)) | R15: =IF($A15="","",IF($Q15=$Q14,$R14+1,1)) | S15: =IF($A15="","",IF(AND($A15=$A14,$B15=$B14),0,1)) | T15: =IF($A15="","",IF($S15=1,COUNTIF($S$5:$S15,1),"")) | U15: =IF($D15="","",IFERROR(VLOOKUP($D15,商品マスタ!$A$5:$G$1000,7,FALSE()),0))
J16: =IF($D16="","",IFERROR(VLOOKUP($D16,商品マスタ!$A$5:$G$1000,2,FALSE()),"※商品マスタ未登録")) | K16: =IF($D16="","",IFERROR(VLOOKUP($D16,商品マスタ!$A$5:$G$1000,3,FALSE()),"")) | L16: =IF($D16="","",IF($H16<>"",$H16,IFERROR(VLOOKUP($D16,商品マスタ!$A$5:$G$1000,4,FALSE()),""))) | M16: =IF($D16="","",IFERROR(VLOOKUP($D16,商品マスタ!$A$5:$G$1000,5,FALSE()),0)) | N16: =IF($D16="","",IFERROR(VLOOKUP($D16,商品マスタ!$A$5:$G$1000,6,FALSE()),0)) | O16: =IF($D16="","",ROUND($E16*$F16,0)) | P16: =IF($D16="","",$O16) | Q16: =IF($A16="","",IF($S16=1,$Q15+1,$Q15)) | R16: =IF($A16="","",IF($Q16=$Q15,$R15+1,1)) | S16: =IF($A16="","",IF(AND($A16=$A15,$B16=$B15),0,1)) | T16: =IF($A16="","",IF($S16=1,COUNTIF($S$5:$S16,1),"")) | U16: =IF($D16="","",IFERROR(VLOOKUP($D16,商品マスタ!$A$5:$G$1000,7,FALSE()),0))
J17: =IF($D17="","",IFERROR(VLOOKUP($D17,商品マスタ!$A$5:$G$1000,2,FALSE()),"※商品マスタ未登録")) | K17: =IF($D17="","",IFERROR(VLOOKUP($D17,商品マスタ!$A$5:$G$1000,3,FALSE()),"")) | L17: =IF($D17="","",IF($H17<>"",$H17,IFERROR(VLOOKUP($D17,商品マスタ!$A$5:$G$1000,4,FALSE()),""))) | M17: =IF($D17="","",IFERROR(VLOOKUP($D17,商品マスタ!$A$5:$G$1000,5,FALSE()),0)) | N17: =IF($D17="","",IFERROR(VLOOKUP($D17,商品マスタ!$A$5:$G$1000,6,FALSE()),0)) | O17: =IF($D17="","",ROUND($E17*$F17,0)) | P17: =IF($D17="","",$O17) | Q17: =IF($A17="","",IF($S17=1,$Q16+1,$Q16)) | R17: =IF($A17="","",IF($Q17=$Q16,$R16+1,1)) | S17: =IF($A17="","",IF(AND($A17=$A16,$B17=$B16),0,1)) | T17: =IF($A17="","",IF($S17=1,COUNTIF($S$5:$S17,1),"")) | U17: =IF($D17="","",IFERROR(VLOOKUP($D17,商品マスタ!$A$5:$G$1000,7,FALSE()),0))
J18: =IF($D18="","",IFERROR(VLOOKUP($D18,商品マスタ!$A$5:$G$1000,2,FALSE()),"※商品マスタ未登録")) | K18: =IF($D18="","",IFERROR(VLOOKUP($D18,商品マスタ!$A$5:$G$1000,3,FALSE()),"")) | L18: =IF($D18="","",IF($H18<>"",$H18,IFERROR(VLOOKUP($D18,商品マスタ!$A$5:$G$1000,4,FALSE()),""))) | M18: =IF($D18="","",IFERROR(VLOOKUP($D18,商品マスタ!$A$5:$G$1000,5,FALSE()),0)) | N18: =IF($D18="","",IFERROR(VLOOKUP($D18,商品マスタ!$A$5:$G$1000,6,FALSE()),0)) | O18: =IF($D18="","",ROUND($E18*$F18,0)) | P18: =IF($D18="","",$O18) | Q18: =IF($A18="","",IF($S18=1,$Q17+1,$Q17)) | R18: =IF($A18="","",IF($Q18=$Q17,$R17+1,1)) | S18: =IF($A18="","",IF(AND($A18=$A17,$B18=$B17),0,1)) | T18: =IF($A18="","",IF($S18=1,COUNTIF($S$5:$S18,1),"")) | U18: =IF($D18="","",IFERROR(VLOOKUP($D18,商品マスタ!$A$5:$G$1000,7,FALSE()),0))
... J204: =IF($D204="","",IFERROR(VLOOKUP($D204,商品マスタ!$A$5:$G$1000,2,FALSE()),"※商品マスタ未登録")) | K204: =IF($D204="","",IFERROR(VLOOKUP($D204,商品マスタ!$A$5:$G$1000,3,FALSE()),"")) | L204: =IF($D204="","",IF($H204<>"",$H204,IFERROR(VLOOKUP($D204,商品マスタ!$A$5:$G$1000,4,FALSE()),""))) | M204: =IF($D204="","",IFERROR(VLOOKUP($D204,商品マスタ!$A$5:$G$1000,5,FALSE()),0)) | N204: =IF($D204="","",IFERROR(VLOOKUP($D204,商品マスタ!$A$5:$G$1000,6,FALSE()),0)) | O204: =IF($D204="","",ROUND($E204*$F204,0)) | P204: =IF($D204="","",$O204) | Q204: =IF($A204="","",IF($S204=1,$Q203+1,$Q203)) | R204: =IF($A204="","",IF($Q204=$Q203,$R203+1,1)) | S204: =IF($A204="","",IF(AND($A204=$A203,$B204=$B203),0,1)) | T204: =IF($A204="","",IF($S204=1,COUNTIF($S$5:$S204,1),"")) | U204: =IF($D204="","",IFERROR(VLOOKUP($D204,商品マスタ!$A$5:$G$1000,7,FALSE()),0))

Sheet CSV出力
A1: =IF(入力シート!$A5="","",1) -> 1 | B1: =IF(入力シート!$A5="","",1) -> 1 | C1: =IF(入力シート!$A5="","",0) -> 0 | D1: =IF(入力シート!$A5="","",TEXT(入力シート!A5,"YYYYMMDD")) -> 20260804 | E1: =IF(入力シート!$A5="","",TEXT(入力シート!Q5,"00000000")) -> 00000090 | F1: =IF(入力シート!$A5="","",14) -> 14 | G1: =IF(入力シート!$A5="","",1) -> 1 | H1: =IF(入力シート!$A5="","",1) -> 1 | I1: =IF(入力シート!$A5="","",3) -> 3 | J1: =IF(入力シート!$A5="","",1) -> 1 | K1: =IF(入力シート!$A5="","",入力シート!B5) -> 50 | L1: =IF(入力シート!$A5="","","") | M1: =IF(入力シート!$A5="","","") | N1: =IF(入力シート!$A5="","",入力シート!R5) -> 1 | O1: =IF(入力シート!$A5="","",IF(入力シート!G5="",1,入力シート!G5)) -> 1 | P1: =IF(入力シート!$A5="","",入力シート!D5) -> 2 | Q1: =IF(入力シート!$A5="","","") | R1: =IF(入力シート!$A5="","",入力シート!J5) -> 黄肌鮪プレートA | S1: =IF(入力シート!$A5="","",入力シート!L5) -> 30 | T1: =IF(入力シート!$A5="","",入力シート!K5) -> kg | U1: =IF(入力シート!$A5="","",0) -> 0 | V1: =IF(入力シート!$A5="","",0) -> 0 | W1: =IF(入力シート!$A5="","","0000") -> 0000 | X1: =IF(入力シート!$A5="","",入力シート!E5) -> 1000 | Y1: =IF(入力シート!$A5="","",入力シート!F5) -> 2700 | Z1: =IF(入力シート!$A5="","",入力シート!O5) -> 2700000 | AA1: =IF(入力シート!$A5="","","") | AB1: =IF(入力シート!$A5="","",入力シート!P5) -> 2700000 | AC1: =IF(入力シート!$A5="","",入力シート!U5) -> 0 | AD1: =IF(入力シート!$A5="","",0) -> 0 | AE1: =IF(入力シート!$A5="","",入力シート!I5) -> 0 | AF1: =IF(入力シート!$A5="","",入力シート!M5) -> 1 | AG1: =IF(入力シート!$A5="","",入力シート!N5) -> 1 | AH1: =IF(入力シート!$A5="","","") | AI1: =IF(入力シート!$A5="","","") | AJ1: =IF(入力シート!$A5="","","") | AK1: =IF(入力シート!$A5="","",2) -> 2 | AL1: =IF(入力シート!$A5="","","") | AM1: =IF(入力シート!$A5="","","") | AN1: =IF(入力シート!$A5="","",入力シート!C5) -> 株式会社オリエンタルフーズ | AO1: =IF(入力シート!$A5="","","") | AP1: =IF(入力シート!$A5="","","") | AQ1: =IF(入力シート!$A5="","","") | AT1: (内部計算用/非表示予定)
A2: =IF(入力シート!$A6="","",1) -> 1 | B2: =IF(入力シート!$A6="","",1) -> 1 | C2: =IF(入力シート!$A6="","",0) -> 0 | D2: =IF(入力シート!$A6="","",TEXT(入力シート!A6,"YYYYMMDD")) -> 20260804 | E2: =IF(入力シート!$A6="","",TEXT(入力シート!Q6,"00000000")) -> 00000090 | F2: =IF(入力シート!$A6="","",14) -> 14 | G2: =IF(入力シート!$A6="","",1) -> 1 | H2: =IF(入力シート!$A6="","",1) -> 1 | I2: =IF(入力シート!$A6="","",3) -> 3 | J2: =IF(入力シート!$A6="","",1) -> 1 | K2: =IF(入力シート!$A6="","",入力シート!B6) -> 50 | L2: =IF(入力シート!$A6="","","") | M2: =IF(入力シート!$A6="","","") | N2: =IF(入力シート!$A6="","",入力シート!R6) -> 2 | O2: =IF(入力シート!$A6="","",IF(入力シート!G6="",1,入力シート!G6)) -> 1 | P2: =IF(入力シート!$A6="","",入力シート!D6) -> 3 | Q2: =IF(入力シート!$A6="","","") | R2: =IF(入力シート!$A6="","",入力シート!J6) -> 黄肌鮪プレートB | S2: =IF(入力シート!$A6="","",入力シート!L6) -> 30 | T2: =IF(入力シート!$A6="","",入力シート!K6) -> kg | U2: =IF(入力シート!$A6="","",0) -> 0 | V2: =IF(入力シート!$A6="","",0) -> 0 | W2: =IF(入力シート!$A6="","","0000") -> 0000 | X2: =IF(入力シート!$A6="","",入力シート!E6) -> 1000 | Y2: =IF(入力シート!$A6="","",入力シート!F6) -> 2450 | Z2: =IF(入力シート!$A6="","",入力シート!O6) -> 2450000 | AA2: =IF(入力シート!$A6="","","") | AB2: =IF(入力シート!$A6="","",入力シート!P6) -> 2450000 | AC2: =IF(入力シート!$A6="","",入力シート!U6) -> 0 | AD2: =IF(入力シート!$A6="","",0) -> 0 | AE2: =IF(入力シート!$A6="","",入力シート!I6) -> 0 | AF2: =IF(入力シート!$A6="","",入力シート!M6) -> 1 | AG2: =IF(入力シート!$A6="","",入力シート!N6) -> 1 | AH2: =IF(入力シート!$A6="","","") | AI2: =IF(入力シート!$A6="","","") | AJ2: =IF(入力シート!$A6="","","") | AK2: =IF(入力シート!$A6="","",2) -> 2 | AL2: =IF(入力シート!$A6="","","") | AM2: =IF(入力シート!$A6="","","") | AN2: =IF(入力シート!$A6="","",入力シート!C6) -> 株式会社オリエンタルフーズ | AO2: =IF(入力シート!$A6="","","") | AP2: =IF(入力シート!$A6="","","") | AQ2: =IF(入力シート!$A6="","","")
A3: =IF(入力シート!$A7="","",1) | B3: =IF(入力シート!$A7="","",1) | C3: =IF(入力シート!$A7="","",0) | D3: =IF(入力シート!$A7="","",TEXT(入力シート!A7,"YYYYMMDD")) | E3: =IF(入力シート!$A7="","",TEXT(入力シート!Q7,"00000000")) | F3: =IF(入力シート!$A7="","",14) | G3: =IF(入力シート!$A7="","",1) | H3: =IF(入力シート!$A7="","",1) | I3: =IF(入力シート!$A7="","",3) | J3: =IF(入力シート!$A7="","",1) | K3: =IF(入力シート!$A7="","",入力シート!B7) | L3: =IF(入力シート!$A7="","","") | M3: =IF(入力シート!$A7="","","") | N3: =IF(入力シート!$A7="","",入力シート!R7) | O3: =IF(入力シート!$A7="","",IF(入力シート!G7="",1,入力シート!G7)) | P3: =IF(入力シート!$A7="","",入力シート!D7) | Q3: =IF(入力シート!$A7="","","") | R3: =IF(入力シート!$A7="","",入力シート!J7) | S3: =IF(入力シート!$A7="","",入力シート!L7) | T3: =IF(入力シート!$A7="","",入力シート!K7) | U3: =IF(入力シート!$A7="","",0) | V3: =IF(入力シート!$A7="","",0) | W3: =IF(入力シート!$A7="","","0000") | X3: =IF(入力シート!$A7="","",入力シート!E7) | Y3: =IF(入力シート!$A7="","",入力シート!F7) | Z3: =IF(入力シート!$A7="","",入力シート!O7) | AA3: =IF(入力シート!$A7="","","") | AB3: =IF(入力シート!$A7="","",入力シート!P7) | AC3: =IF(入力シート!$A7="","",入力シート!U7) | AD3: =IF(入力シート!$A7="","",0) | AE3: =IF(入力シート!$A7="","",入力シート!I7) | AF3: =IF(入力シート!$A7="","",入力シート!M7) | AG3: =IF(入力シート!$A7="","",入力シート!N7) | AH3: =IF(入力シート!$A7="","","") | AI3: =IF(入力シート!$A7="","","") | AJ3: =IF(入力シート!$A7="","","") | AK3: =IF(入力シート!$A7="","",2) | AL3: =IF(入力シート!$A7="","","") | AM3: =IF(入力シート!$A7="","","") | AN3: =IF(入力シート!$A7="","",入力シート!C7) | AO3: =IF(入力シート!$A7="","","") | AP3: =IF(入力シート!$A7="","","") | AQ3: =IF(入力シート!$A7="","","")
A4: =IF(入力シート!$A8="","",1) | B4: =IF(入力シート!$A8="","",1) | C4: =IF(入力シート!$A8="","",0) | D4: =IF(入力シート!$A8="","",TEXT(入力シート!A8,"YYYYMMDD")) | E4: =IF(入力シート!$A8="","",TEXT(入力シート!Q8,"00000000")) | F4: =IF(入力シート!$A8="","",14) | G4: =IF(入力シート!$A8="","",1) | H4: =IF(入力シート!$A8="","",1) | I4: =IF(入力シート!$A8="","",3) | J4: =IF(入力シート!$A8="","",1) | K4: =IF(入力シート!$A8="","",入力シート!B8) | L4: =IF(入力シート!$A8="","","") | M4: =IF(入力シート!$A8="","","") | N4: =IF(入力シート!$A8="","",入力シート!R8) | O4: =IF(入力シート!$A8="","",IF(入力シート!G8="",1,入力シート!G8)) | P4: =IF(入力シート!$A8="","",入力シート!D8) | Q4: =IF(入力シート!$A8="","","") | R4: =IF(入力シート!$A8="","",入力シート!J8) | S4: =IF(入力シート!$A8="","",入力シート!L8) | T4: =IF(入力シート!$A8="","",入力シート!K8) | U4: =IF(入力シート!$A8="","",0) | V4: =IF(入力シート!$A8="","",0) | W4: =IF(入力シート!$A8="","","0000") | X4: =IF(入力シート!$A8="","",入力シート!E8) | Y4: =IF(入力シート!$A8="","",入力シート!F8) | Z4: =IF(入力シート!$A8="","",入力シート!O8) | AA4: =IF(入力シート!$A8="","","") | AB4: =IF(入力シート!$A8="","",入力シート!P8) | AC4: =IF(入力シート!$A8="","",入力シート!U8) | AD4: =IF(入力シート!$A8="","",0) | AE4: =IF(入力シート!$A8="","",入力シート!I8) | AF4: =IF(入力シート!$A8="","",入力シート!M8) | AG4: =IF(入力シート!$A8="","",入力シート!N8) | AH4: =IF(入力シート!$A8="","","") | AI4: =IF(入力シート!$A8="","","") | AJ4: =IF(入力シート!$A8="","","") | AK4: =IF(入力シート!$A8="","",2) | AL4: =IF(入力シート!$A8="","","") | AM4: =IF(入力シート!$A8="","","") | AN4: =IF(入力シート!$A8="","",入力シート!C8) | AO4: =IF(入力シート!$A8="","","") | AP4: =IF(入力シート!$A8="","","") | AQ4: =IF(入力シート!$A8="","","")
A5: =IF(入力シート!$A9="","",1) | B5: =IF(入力シート!$A9="","",1) | C5: =IF(入力シート!$A9="","",0) | D5: =IF(入力シート!$A9="","",TEXT(入力シート!A9,"YYYYMMDD")) | E5: =IF(入力シート!$A9="","",TEXT(入力シート!Q9,"00000000")) | F5: =IF(入力シート!$A9="","",14) | G5: =IF(入力シート!$A9="","",1) | H5: =IF(入力シート!$A9="","",1) | I5: =IF(入力シート!$A9="","",3) | J5: =IF(入力シート!$A9="","",1) | K5: =IF(入力シート!$A9="","",入力シート!B9) | L5: =IF(入力シート!$A9="","","") | M5: =IF(入力シート!$A9="","","") | N5: =IF(入力シート!$A9="","",入力シート!R9) | O5: =IF(入力シート!$A9="","",IF(入力シート!G9="",1,入力シート!G9)) | P5: =IF(入力シート!$A9="","",入力シート!D9) | Q5: =IF(入力シート!$A9="","","") | R5: =IF(入力シート!$A9="","",入力シート!J9) | S5: =IF(入力シート!$A9="","",入力シート!L9) | T5: =IF(入力シート!$A9="","",入力シート!K9) | U5: =IF(入力シート!$A9="","",0) | V5: =IF(入力シート!$A9="","",0) | W5: =IF(入力シート!$A9="","","0000") | X5: =IF(入力シート!$A9="","",入力シート!E9) | Y5: =IF(入力シート!$A9="","",入力シート!F9) | Z5: =IF(入力シート!$A9="","",入力シート!O9) | AA5: =IF(入力シート!$A9="","","") | AB5: =IF(入力シート!$A9="","",入力シート!P9) | AC5: =IF(入力シート!$A9="","",入力シート!U9) | AD5: =IF(入力シート!$A9="","",0) | AE5: =IF(入力シート!$A9="","",入力シート!I9) | AF5: =IF(入力シート!$A9="","",入力シート!M9) | AG5: =IF(入力シート!$A9="","",入力シート!N9) | AH5: =IF(入力シート!$A9="","","") | AI5: =IF(入力シート!$A9="","","") | AJ5: =IF(入力シート!$A9="","","") | AK5: =IF(入力シート!$A9="","",2) | AL5: =IF(入力シート!$A9="","","") | AM5: =IF(入力シート!$A9="","","") | AN5: =IF(入力シート!$A9="","",入力シート!C9) | AO5: =IF(入力シート!$A9="","","") | AP5: =IF(入力シート!$A9="","","") | AQ5: =IF(入力シート!$A9="","","")
A6: =IF(入力シート!$A10="","",1) | B6: =IF(入力シート!$A10="","",1) | C6: =IF(入力シート!$A10="","",0) | D6: =IF(入力シート!$A10="","",TEXT(入力シート!A10,"YYYYMMDD")) | E6: =IF(入力シート!$A10="","",TEXT(入力シート!Q10,"00000000")) | F6: =IF(入力シート!$A10="","",14) | G6: =IF(入力シート!$A10="","",1) | H6: =IF(入力シート!$A10="","",1) | I6: =IF(入力シート!$A10="","",3) | J6: =IF(入力シート!$A10="","",1) | K6: =IF(入力シート!$A10="","",入力シート!B10) | L6: =IF(入力シート!$A10="","","") | M6: =IF(入力シート!$A10="","","") | N6: =IF(入力シート!$A10="","",入力シート!R10) | O6: =IF(入力シート!$A10="","",IF(入力シート!G10="",1,入力シート!G10)) | P6: =IF(入力シート!$A10="","",入力シート!D10) | Q6: =IF(入力シート!$A10="","","") | R6: =IF(入力シート!$A10="","",入力シート!J10) | S6: =IF(入力シート!$A10="","",入力シート!L10) | T6: =IF(入力シート!$A10="","",入力シート!K10) | U6: =IF(入力シート!$A10="","",0) | V6: =IF(入力シート!$A10="","",0) | W6: =IF(入力シート!$A10="","","0000") | X6: =IF(入力シート!$A10="","",入力シート!E10) | Y6: =IF(入力シート!$A10="","",入力シート!F10) | Z6: =IF(入力シート!$A10="","",入力シート!O10) | AA6: =IF(入力シート!$A10="","","") | AB6: =IF(入力シート!$A10="","",入力シート!P10) | AC6: =IF(入力シート!$A10="","",入力シート!U10) | AD6: =IF(入力シート!$A10="","",0) | AE6: =IF(入力シート!$A10="","",入力シート!I10) | AF6: =IF(入力シート!$A10="","",入力シート!M10) | AG6: =IF(入力シート!$A10="","",入力シート!N10) | AH6: =IF(入力シート!$A10="","","") | AI6: =IF(入力シート!$A10="","","") | AJ6: =IF(入力シート!$A10="","","") | AK6: =IF(入力シート!$A10="","",2) | AL6: =IF(入力シート!$A10="","","") | AM6: =IF(入力シート!$A10="","","") | AN6: =IF(入力シート!$A10="","",入力シート!C10) | AO6: =IF(入力シート!$A10="","","") | AP6: =IF(入力シート!$A10="","","") | AQ6: =IF(入力シート!$A10="","","")
A7: =IF(入力シート!$A11="","",1) | B7: =IF(入力シート!$A11="","",1) | C7: =IF(入力シート!$A11="","",0) | D7: =IF(入力シート!$A11="","",TEXT(入力シート!A11,"YYYYMMDD")) | E7: =IF(入力シート!$A11="","",TEXT(入力シート!Q11,"00000000")) | F7: =IF(入力シート!$A11="","",14) | G7: =IF(入力シート!$A11="","",1) | H7: =IF(入力シート!$A11="","",1) | I7: =IF(入力シート!$A11="","",3) | J7: =IF(入力シート!$A11="","",1) | K7: =IF(入力シート!$A11="","",入力シート!B11) | L7: =IF(入力シート!$A11="","","") | M7: =IF(入力シート!$A11="","","") | N7: =IF(入力シート!$A11="","",入力シート!R11) | O7: =IF(入力シート!$A11="","",IF(入力シート!G11="",1,入力シート!G11)) | P7: =IF(入力シート!$A11="","",入力シート!D11) | Q7: =IF(入力シート!$A11="","","") | R7: =IF(入力シート!$A11="","",入力シート!J11) | S7: =IF(入力シート!$A11="","",入力シート!L11) | T7: =IF(入力シート!$A11="","",入力シート!K11) | U7: =IF(入力シート!$A11="","",0) | V7: =IF(入力シート!$A11="","",0) | W7: =IF(入力シート!$A11="","","0000") | X7: =IF(入力シート!$A11="","",入力シート!E11) | Y7: =IF(入力シート!$A11="","",入力シート!F11) | Z7: =IF(入力シート!$A11="","",入力シート!O11) | AA7: =IF(入力シート!$A11="","","") | AB7: =IF(入力シート!$A11="","",入力シート!P11) | AC7: =IF(入力シート!$A11="","",入力シート!U11) | AD7: =IF(入力シート!$A11="","",0) | AE7: =IF(入力シート!$A11="","",入力シート!I11) | AF7: =IF(入力シート!$A11="","",入力シート!M11) | AG7: =IF(入力シート!$A11="","",入力シート!N11) | AH7: =IF(入力シート!$A11="","","") | AI7: =IF(入力シート!$A11="","","") | AJ7: =IF(入力シート!$A11="","","") | AK7: =IF(入力シート!$A11="","",2) | AL7: =IF(入力シート!$A11="","","") | AM7: =IF(入力シート!$A11="","","") | AN7: =IF(入力シート!$A11="","",入力シート!C11) | AO7: =IF(入力シート!$A11="","","") | AP7: =IF(入力シート!$A11="","","") | AQ7: =IF(入力シート!$A11="","","")
A8: =IF(入力シート!$A12="","",1) | B8: =IF(入力シート!$A12="","",1) | C8: =IF(入力シート!$A12="","",0) | D8: =IF(入力シート!$A12="","",TEXT(入力シート!A12,"YYYYMMDD")) | E8: =IF(入力シート!$A12="","",TEXT(入力シート!Q12,"00000000")) | F8: =IF(入力シート!$A12="","",14) | G8: =IF(入力シート!$A12="","",1) | H8: =IF(入力シート!$A12="","",1) | I8: =IF(入力シート!$A12="","",3) | J8: =IF(入力シート!$A12="","",1) | K8: =IF(入力シート!$A12="","",入力シート!B12) | L8: =IF(入力シート!$A12="","","") | M8: =IF(入力シート!$A12="","","") | N8: =IF(入力シート!$A12="","",入力シート!R12) | O8: =IF(入力シート!$A12="","",IF(入力シート!G12="",1,入力シート!G12)) | P8: =IF(入力シート!$A12="","",入力シート!D12) | Q8: =IF(入力シート!$A12="","","") | R8: =IF(入力シート!$A12="","",入力シート!J12) | S8: =IF(入力シート!$A12="","",入力シート!L12) | T8: =IF(入力シート!$A12="","",入力シート!K12) | U8: =IF(入力シート!$A12="","",0) | V8: =IF(入力シート!$A12="","",0) | W8: =IF(入力シート!$A12="","","0000") | X8: =IF(入力シート!$A12="","",入力シート!E12) | Y8: =IF(入力シート!$A12="","",入力シート!F12) | Z8: =IF(入力シート!$A12="","",入力シート!O12) | AA8: =IF(入力シート!$A12="","","") | AB8: =IF(入力シート!$A12="","",入力シート!P12) | AC8: =IF(入力シート!$A12="","",入力シート!U12) | AD8: =IF(入力シート!$A12="","",0) | AE8: =IF(入力シート!$A12="","",入力シート!I12) | AF8: =IF(入力シート!$A12="","",入力シート!M12) | AG8: =IF(入力シート!$A12="","",入力シート!N12) | AH8: =IF(入力シート!$A12="","","") | AI8: =IF(入力シート!$A12="","","") | AJ8: =IF(入力シート!$A12="","","") | AK8: =IF(入力シート!$A12="","",2) | AL8: =IF(入力シート!$A12="","","") | AM8: =IF(入力シート!$A12="","","") | AN8: =IF(入力シート!$A12="","",入力シート!C12) | AO8: =IF(入力シート!$A12="","","") | AP8: =IF(入力シート!$A12="","","") | AQ8: =IF(入力シート!$A12="","","")
A9: =IF(入力シート!$A13="","",1) | B9: =IF(入力シート!$A13="","",1) | C9: =IF(入力シート!$A13="","",0) | D9: =IF(入力シート!$A13="","",TEXT(入力シート!A13,"YYYYMMDD")) | E9: =IF(入力シート!$A13="","",TEXT(入力シート!Q13,"00000000")) | F9: =IF(入力シート!$A13="","",14) | G9: =IF(入力シート!$A13="","",1) | H9: =IF(入力シート!$A13="","",1) | I9: =IF(入力シート!$A13="","",3) | J9: =IF(入力シート!$A13="","",1) | K9: =IF(入力シート!$A13="","",入力シート!B13) | L9: =IF(入力シート!$A13="","","") | M9: =IF(入力シート!$A13="","","") | N9: =IF(入力シート!$A13="","",入力シート!R13) | O9: =IF(入力シート!$A13="","",IF(入力シート!G13="",1,入力シート!G13)) | P9: =IF(入力シート!$A13="","",入力シート!D13) | Q9: =IF(入力シート!$A13="","","") | R9: =IF(入力シート!$A13="","",入力シート!J13) | S9: =IF(入力シート!$A13="","",入力シート!L13) | T9: =IF(入力シート!$A13="","",入力シート!K13) | U9: =IF(入力シート!$A13="","",0) | V9: =IF(入力シート!$A13="","",0) | W9: =IF(入力シート!$A13="","","0000") | X9: =IF(入力シート!$A13="","",入力シート!E13) | Y9: =IF(入力シート!$A13="","",入力シート!F13) | Z9: =IF(入力シート!$A13="","",入力シート!O13) | AA9: =IF(入力シート!$A13="","","") | AB9: =IF(入力シート!$A13="","",入力シート!P13) | AC9: =IF(入力シート!$A13="","",入力シート!U13) | AD9: =IF(入力シート!$A13="","",0) | AE9: =IF(入力シート!$A13="","",入力シート!I13) | AF9: =IF(入力シート!$A13="","",入力シート!M13) | AG9: =IF(入力シート!$A13="","",入力シート!N13) | AH9: =IF(入力シート!$A13="","","") | AI9: =IF(入力シート!$A13="","","") | AJ9: =IF(入力シート!$A13="","","") | AK9: =IF(入力シート!$A13="","",2) | AL9: =IF(入力シート!$A13="","","") | AM9: =IF(入力シート!$A13="","","") | AN9: =IF(入力シート!$A13="","",入力シート!C13) | AO9: =IF(入力シート!$A13="","","") | AP9: =IF(入力シート!$A13="","","") | AQ9: =IF(入力シート!$A13="","","")
A10: =IF(入力シート!$A14="","",1) | B10: =IF(入力シート!$A14="","",1) | C10: =IF(入力シート!$A14="","",0) | D10: =IF(入力シート!$A14="","",TEXT(入力シート!A14,"YYYYMMDD")) | E10: =IF(入力シート!$A14="","",TEXT(入力シート!Q14,"00000000")) | F10: =IF(入力シート!$A14="","",14) | G10: =IF(入力シート!$A14="","",1) | H10: =IF(入力シート!$A14="","",1) | I10: =IF(入力シート!$A14="","",3) | J10: =IF(入力シート!$A14="","",1) | K10: =IF(入力シート!$A14="","",入力シート!B14) | L10: =IF(入力シート!$A14="","","") | M10: =IF(入力シート!$A14="","","") | N10: =IF(入力シート!$A14="","",入力シート!R14) | O10: =IF(入力シート!$A14="","",IF(入力シート!G14="",1,入力シート!G14)) | P10: =IF(入力シート!$A14="","",入力シート!D14) | Q10: =IF(入力シート!$A14="","","") | R10: =IF(入力シート!$A14="","",入力シート!J14) | S10: =IF(入力シート!$A14="","",入力シート!L14) | T10: =IF(入力シート!$A14="","",入力シート!K14) | U10: =IF(入力シート!$A14="","",0) | V10: =IF(入力シート!$A14="","",0) | W10: =IF(入力シート!$A14="","","0000") | X10: =IF(入力シート!$A14="","",入力シート!E14) | Y10: =IF(入力シート!$A14="","",入力シート!F14) | Z10: =IF(入力シート!$A14="","",入力シート!O14) | AA10: =IF(入力シート!$A14="","","") | AB10: =IF(入力シート!$A14="","",入力シート!P14) | AC10: =IF(入力シート!$A14="","",入力シート!U14) | AD10: =IF(入力シート!$A14="","",0) | AE10: =IF(入力シート!$A14="","",入力シート!I14) | AF10: =IF(入力シート!$A14="","",入力シート!M14) | AG10: =IF(入力シート!$A14="","",入力シート!N14) | AH10: =IF(入力シート!$A14="","","") | AI10: =IF(入力シート!$A14="","","") | AJ10: =IF(入力シート!$A14="","","") | AK10: =IF(入力シート!$A14="","",2) | AL10: =IF(入力シート!$A14="","","") | AM10: =IF(入力シート!$A14="","","") | AN10: =IF(入力シート!$A14="","",入力シート!C14) | AO10: =IF(入力シート!$A14="","","") | AP10: =IF(入力シート!$A14="","","") | AQ10: =IF(入力シート!$A14="","","")
A11: =IF(入力シート!$A15="","",1) | B11: =IF(入力シート!$A15="","",1) | C11: =IF(入力シート!$A15="","",0) | D11: =IF(入力シート!$A15="","",TEXT(入力シート!A15,"YYYYMMDD")) | E11: =IF(入力シート!$A15="","",TEXT(入力シート!Q15,"00000000")) | F11: =IF(入力シート!$A15="","",14) | G11: =IF(入力シート!$A15="","",1) | H11: =IF(入力シート!$A15="","",1) | I11: =IF(入力シート!$A15="","",3) | J11: =IF(入力シート!$A15="","",1) | K11: =IF(入力シート!$A15="","",入力シート!B15) | L11: =IF(入力シート!$A15="","","") | M11: =IF(入力シート!$A15="","","") | N11: =IF(入力シート!$A15="","",入力シート!R15) | O11: =IF(入力シート!$A15="","",IF(入力シート!G15="",1,入力シート!G15)) | P11: =IF(入力シート!$A15="","",入力シート!D15) | Q11: =IF(入力シート!$A15="","","") | R11: =IF(入力シート!$A15="","",入力シート!J15) | S11: =IF(入力シート!$A15="","",入力シート!L15) | T11: =IF(入力シート!$A15="","",入力シート!K15) | U11: =IF(入力シート!$A15="","",0) | V11: =IF(入力シート!$A15="","",0) | W11: =IF(入力シート!$A15="","","0000") | X11: =IF(入力シート!$A15="","",入力シート!E15) | Y11: =IF(入力シート!$A15="","",入力シート!F15) | Z11: =IF(入力シート!$A15="","",入力シート!O15) | AA11: =IF(入力シート!$A15="","","") | AB11: =IF(入力シート!$A15="","",入力シート!P15) | AC11: =IF(入力シート!$A15="","",入力シート!U15) | AD11: =IF(入力シート!$A15="","",0) | AE11: =IF(入力シート!$A15="","",入力シート!I15) | AF11: =IF(入力シート!$A15="","",入力シート!M15) | AG11: =IF(入力シート!$A15="","",入力シート!N15) | AH11: =IF(入力シート!$A15="","","") | AI11: =IF(入力シート!$A15="","","") | AJ11: =IF(入力シート!$A15="","","") | AK11: =IF(入力シート!$A15="","",2) | AL11: =IF(入力シート!$A15="","","") | AM11: =IF(入力シート!$A15="","","") | AN11: =IF(入力シート!$A15="","",入力シート!C15) | AO11: =IF(入力シート!$A15="","","") | AP11: =IF(入力シート!$A15="","","") | AQ11: =IF(入力シート!$A15="","","")
A12: =IF(入力シート!$A16="","",1) | B12: =IF(入力シート!$A16="","",1) | C12: =IF(入力シート!$A16="","",0) | D12: =IF(入力シート!$A16="","",TEXT(入力シート!A16,"YYYYMMDD")) | E12: =IF(入力シート!$A16="","",TEXT(入力シート!Q16,"00000000")) | F12: =IF(入力シート!$A16="","",14) | G12: =IF(入力シート!$A16="","",1) | H12: =IF(入力シート!$A16="","",1) | I12: =IF(入力シート!$A16="","",3) | J12: =IF(入力シート!$A16="","",1) | K12: =IF(入力シート!$A16="","",入力シート!B16) | L12: =IF(入力シート!$A16="","","") | M12: =IF(入力シート!$A16="","","") | N12: =IF(入力シート!$A16="","",入力シート!R16) | O12: =IF(入力シート!$A16="","",IF(入力シート!G16="",1,入力シート!G16)) | P12: =IF(入力シート!$A16="","",入力シート!D16) | Q12: =IF(入力シート!$A16="","","") | R12: =IF(入力シート!$A16="","",入力シート!J16) | S12: =IF(入力シート!$A16="","",入力シート!L16) | T12: =IF(入力シート!$A16="","",入力シート!K16) | U12: =IF(入力シート!$A16="","",0) | V12: =IF(入力シート!$A16="","",0) | W12: =IF(入力シート!$A16="","","0000") | X12: =IF(入力シート!$A16="","",入力シート!E16) | Y12: =IF(入力シート!$A16="","",入力シート!F16) | Z12: =IF(入力シート!$A16="","",入力シート!O16) | AA12: =IF(入力シート!$A16="","","") | AB12: =IF(入力シート!$A16="","",入力シート!P16) | AC12: =IF(入力シート!$A16="","",入力シート!U16) | AD12: =IF(入力シート!$A16="","",0) | AE12: =IF(入力シート!$A16="","",入力シート!I16) | AF12: =IF(入力シート!$A16="","",入力シート!M16) | AG12: =IF(入力シート!$A16="","",入力シート!N16) | AH12: =IF(入力シート!$A16="","","") | AI12: =IF(入力シート!$A16="","","") | AJ12: =IF(入力シート!$A16="","","") | AK12: =IF(入力シート!$A16="","",2) | AL12: =IF(入力シート!$A16="","","") | AM12: =IF(入力シート!$A16="","","") | AN12: =IF(入力シート!$A16="","",入力シート!C16) | AO12: =IF(入力シート!$A16="","","") | AP12: =IF(入力シート!$A16="","","") | AQ12: =IF(入力シート!$A16="","","")
A13: =IF(入力シート!$A17="","",1) | B13: =IF(入力シート!$A17="","",1) | C13: =IF(入力シート!$A17="","",0) | D13: =IF(入力シート!$A17="","",TEXT(入力シート!A17,"YYYYMMDD")) | E13: =IF(入力シート!$A17="","",TEXT(入力シート!Q17,"00000000")) | F13: =IF(入力シート!$A17="","",14) | G13: =IF(入力シート!$A17="","",1) | H13: =IF(入力シート!$A17="","",1) | I13: =IF(入力シート!$A17="","",3) | J13: =IF(入力シート!$A17="","",1) | K13: =IF(入力シート!$A17="","",入力シート!B17) | L13: =IF(入力シート!$A17="","","") | M13: =IF(入力シート!$A17="","","") | N13: =IF(入力シート!$A17="","",入力シート!R17) | O13: =IF(入力シート!$A17="","",IF(入力シート!G17="",1,入力シート!G17)) | P13: =IF(入力シート!$A17="","",入力シート!D17) | Q13: =IF(入力シート!$A17="","","") | R13: =IF(入力シート!$A17="","",入力シート!J17) | S13: =IF(入力シート!$A17="","",入力シート!L17) | T13: =IF(入力シート!$A17="","",入力シート!K17) | U13: =IF(入力シート!$A17="","",0) | V13: =IF(入力シート!$A17="","",0) | W13: =IF(入力シート!$A17="","","0000") | X13: =IF(入力シート!$A17="","",入力シート!E17) | Y13: =IF(入力シート!$A17="","",入力シート!F17) | Z13: =IF(入力シート!$A17="","",入力シート!O17) | AA13: =IF(入力シート!$A17="","","") | AB13: =IF(入力シート!$A17="","",入力シート!P17) | AC13: =IF(入力シート!$A17="","",入力シート!U17) | AD13: =IF(入力シート!$A17="","",0) | AE13: =IF(入力シート!$A17="","",入力シート!I17) | AF13: =IF(入力シート!$A17="","",入力シート!M17) | AG13: =IF(入力シート!$A17="","",入力シート!N17) | AH13: =IF(入力シート!$A17="","","") | AI13: =IF(入力シート!$A17="","","") | AJ13: =IF(入力シート!$A17="","","") | AK13: =IF(入力シート!$A17="","",2) | AL13: =IF(入力シート!$A17="","","") | AM13: =IF(入力シート!$A17="","","") | AN13: =IF(入力シート!$A17="","",入力シート!C17) | AO13: =IF(入力シート!$A17="","","") | AP13: =IF(入力シート!$A17="","","") | AQ13: =IF(入力シート!$A17="","","")
... A200: =IF(入力シート!$A204="","",1) | B200: =IF(入力シート!$A204="","",1) | C200: =IF(入力シート!$A204="","",0) | D200: =IF(入力シート!$A204="","",TEXT(入力シート!A204,"YYYYMMDD")) | E200: =IF(入力シート!$A204="","",TEXT(入力シート!Q204,"00000000")) | F200: =IF(入力シート!$A204="","",14) | G200: =IF(入力シート!$A204="","",1) | H200: =IF(入力シート!$A204="","",1) | I200: =IF(入力シート!$A204="","",3) | J200: =IF(入力シート!$A204="","",1) | K200: =IF(入力シート!$A204="","",入力シート!B204) | L200: =IF(入力シート!$A204="","","") | M200: =IF(入力シート!$A204="","","") | N200: =IF(入力シート!$A204="","",入力シート!R204) | O200: =IF(入力シート!$A204="","",IF(入力シート!G204="",1,入力シート!G204)) | P200: =IF(入力シート!$A204="","",入力シート!D204) | Q200: =IF(入力シート!$A204="","","") | R200: =IF(入力シート!$A204="","",入力シート!J204) | S200: =IF(入力シート!$A204="","",入力シート!L204) | T200: =IF(入力シート!$A204="","",入力シート!K204) | U200: =IF(入力シート!$A204="","",0) | V200: =IF(入力シート!$A204="","",0) | W200: =IF(入力シート!$A204="","","0000") | X200: =IF(入力シート!$A204="","",入力シート!E204) | Y200: =IF(入力シート!$A204="","",入力シート!F204) | Z200: =IF(入力シート!$A204="","",入力シート!O204) | AA200: =IF(入力シート!$A204="","","") | AB200: =IF(入力シート!$A204="","",入力シート!P204) | AC200: =IF(入力シート!$A204="","",入力シート!U204) | AD200: =IF(入力シート!$A204="","",0) | AE200: =IF(入力シート!$A204="","",入力シート!I204) | AF200: =IF(入力シート!$A204="","",入力シート!M204) | AG200: =IF(入力シート!$A204="","",入力シート!N204) | AH200: =IF(入力シート!$A204="","","") | AI200: =IF(入力シート!$A204="","","") | AJ200: =IF(入力シート!$A204="","","") | AK200: =IF(入力シート!$A204="","",2) | AL200: =IF(入力シート!$A204="","","") | AM200: =IF(入力シート!$A204="","","") | AN200: =IF(入力シート!$A204="","",入力シート!C204) | AO200: =IF(入力シート!$A204="","","") | AP200: =IF(入力シート!$A204="","","") | AQ200: =IF(入力シート!$A204="","","")
A201: =IF(AT201="","",1) -> 1 | B201: =IF(AT201="","",1) -> 1 | C201: =IF(AT201="","",0) -> 0 | D201: =IF(AT201="","",TEXT(INDEX(入力シート!$A$5:$A$204,AT201),"YYYYMMDD")) -> 20260804 | E201: =IF(AT201="","",TEXT(INDEX(入力シート!$Q$5:$Q$204,AT201),"00000000")) -> 00000090 | F201: =IF(AT201="","",14) -> 14 | G201: =IF(AT201="","",1) -> 1 | H201: =IF(AT201="","",1) -> 1 | I201: =IF(AT201="","",3) -> 3 | J201: =IF(AT201="","",1) -> 1 | K201: =IF(AT201="","",INDEX(入力シート!$B$5:$B$204,AT201)) -> 50 | L201: =IF(AT201="","","") | M201: =IF(AT201="","","") | N201: =IF(AT201="","",COUNTIF(入力シート!$Q$5:$Q$204,INDEX(入力シート!$Q$5:$Q$204,AT201))+1) -> 3 | O201: =IF(AT201="","",99) -> 99 | P201: =IF(AT201="","","") | Q201: =IF(AT201="","","") | R201: =IF(AT201="","","消費税") -> 消費税 | S201: =IF(AT201="","",0) -> 0 | T201: =IF(AT201="","","") | U201: =IF(AT201="","",0) -> 0 | V201: =IF(AT201="","",0) -> 0 | W201: =IF(AT201="","","") | X201: =IF(AT201="","",0) -> 0 | Y201: =IF(AT201="","",0) -> 0 | Z201: =IF(AT201="","",ROUNDDOWN(SUMIF(入力シート!$Q$5:$Q$204,INDEX(入力シート!$Q$5:$Q$204,AT201),入力シート!$P$5:$P$204)*IF(INDEX(入力シート!$L$5:$L$204,AT201)=13,0.1,IF(INDEX(入力シート!$L$5:$L$204,AT201)=30,0.08,0)),0)) -> 412000 | AA201: =IF(AT201="","","") | AB201: =IF(AT201="","",0) -> 0 | AC201: =IF(AT201="","",0) -> 0 | AD201: =IF(AT201="","",0) -> 0 | AE201: =IF(AT201="","","") | AF201: =IF(AT201="","",0) -> 0 | AG201: =IF(AT201="","",0) -> 0 | AH201: =IF(AT201="","","") | AI201: =IF(AT201="","","") | AJ201: =IF(AT201="","","") | AK201: =IF(AT201="","",2) -> 2 | AL201: =IF(AT201="","","") | AM201: =IF(AT201="","","") | AN201: =IF(AT201="","",INDEX(入力シート!$C$5:$C$204,AT201)) -> 株式会社オリエンタルフーズ | AO201: =IF(AT201="","","") | AP201: =IF(AT201="","","") | AQ201: =IF(AT201="","","") | AT201: =IFERROR(MATCH(1,入力シート!$T$5:$T$204,0),"") -> 1
A202: =IF(AT202="","",1) | B202: =IF(AT202="","",1) | C202: =IF(AT202="","",0) | D202: =IF(AT202="","",TEXT(INDEX(入力シート!$A$5:$A$204,AT202),"YYYYMMDD")) | E202: =IF(AT202="","",TEXT(INDEX(入力シート!$Q$5:$Q$204,AT202),"00000000")) | F202: =IF(AT202="","",14) | G202: =IF(AT202="","",1) | H202: =IF(AT202="","",1) | I202: =IF(AT202="","",3) | J202: =IF(AT202="","",1) | K202: =IF(AT202="","",INDEX(入力シート!$B$5:$B$204,AT202)) | L202: =IF(AT202="","","") | M202: =IF(AT202="","","") | N202: =IF(AT202="","",COUNTIF(入力シート!$Q$5:$Q$204,INDEX(入力シート!$Q$5:$Q$204,AT202))+1) | O202: =IF(AT202="","",99) | P202: =IF(AT202="","","") | Q202: =IF(AT202="","","") | R202: =IF(AT202="","","消費税") | S202: =IF(AT202="","",0) | T202: =IF(AT202="","","") | U202: =IF(AT202="","",0) | V202: =IF(AT202="","",0) | W202: =IF(AT202="","","") | X202: =IF(AT202="","",0) | Y202: =IF(AT202="","",0) | Z202: =IF(AT202="","",ROUNDDOWN(SUMIF(入力シート!$Q$5:$Q$204,INDEX(入力シート!$Q$5:$Q$204,AT202),入力シート!$P$5:$P$204)*IF(INDEX(入力シート!$L$5:$L$204,AT202)=13,0.1,IF(INDEX(入力シート!$L$5:$L$204,AT202)=30,0.08,0)),0)) | AA202: =IF(AT202="","","") | AB202: =IF(AT202="","",0) | AC202: =IF(AT202="","",0) | AD202: =IF(AT202="","",0) | AE202: =IF(AT202="","","") | AF202: =IF(AT202="","",0) | AG202: =IF(AT202="","",0) | AH202: =IF(AT202="","","") | AI202: =IF(AT202="","","") | AJ202: =IF(AT202="","","") | AK202: =IF(AT202="","",2) | AL202: =IF(AT202="","","") | AM202: =IF(AT202="","","") | AN202: =IF(AT202="","",INDEX(入力シート!$C$5:$C$204,AT202)) | AO202: =IF(AT202="","","") | AP202: =IF(AT202="","","") | AQ202: =IF(AT202="","","") | AT202: =IFERROR(MATCH(2,入力シート!$T$5:$T$204,0),"")
A203: =IF(AT203="","",1) | B203: =IF(AT203="","",1) | C203: =IF(AT203="","",0) | D203: =IF(AT203="","",TEXT(INDEX(入力シート!$A$5:$A$204,AT203),"YYYYMMDD")) | E203: =IF(AT203="","",TEXT(INDEX(入力シート!$Q$5:$Q$204,AT203),"00000000")) | F203: =IF(AT203="","",14) | G203: =IF(AT203="","",1) | H203: =IF(AT203="","",1) | I203: =IF(AT203="","",3) | J203: =IF(AT203="","",1) | K203: =IF(AT203="","",INDEX(入力シート!$B$5:$B$204,AT203)) | L203: =IF(AT203="","","") | M203: =IF(AT203="","","") | N203: =IF(AT203="","",COUNTIF(入力シート!$Q$5:$Q$204,INDEX(入力シート!$Q$5:$Q$204,AT203))+1) | O203: =IF(AT203="","",99) | P203: =IF(AT203="","","") | Q203: =IF(AT203="","","") | R203: =IF(AT203="","","消費税") | S203: =IF(AT203="","",0) | T203: =IF(AT203="","","") | U203: =IF(AT203="","",0) | V203: =IF(AT203="","",0) | W203: =IF(AT203="","","") | X203: =IF(AT203="","",0) | Y203: =IF(AT203="","",0) | Z203: =IF(AT203="","",ROUNDDOWN(SUMIF(入力シート!$Q$5:$Q$204,INDEX(入力シート!$Q$5:$Q$204,AT203),入力シート!$P$5:$P$204)*IF(INDEX(入力シート!$L$5:$L$204,AT203)=13,0.1,IF(INDEX(入力シート!$L$5:$L$204,AT203)=30,0.08,0)),0)) | AA203: =IF(AT203="","","") | AB203: =IF(AT203="","",0) | AC203: =IF(AT203="","",0) | AD203: =IF(AT203="","",0) | AE203: =IF(AT203="","","") | AF203: =IF(AT203="","",0) | AG203: =IF(AT203="","",0) | AH203: =IF(AT203="","","") | AI203: =IF(AT203="","","") | AJ203: =IF(AT203="","","") | AK203: =IF(AT203="","",2) | AL203: =IF(AT203="","","") | AM203: =IF(AT203="","","") | AN203: =IF(AT203="","",INDEX(入力シート!$C$5:$C$204,AT203)) | AO203: =IF(AT203="","","") | AP203: =IF(AT203="","","") | AQ203: =IF(AT203="","","") | AT203: =IFERROR(MATCH(3,入力シート!$T$5:$T$204,0),"")
A204: =IF(AT204="","",1) | B204: =IF(AT204="","",1) | C204: =IF(AT204="","",0) | D204: =IF(AT204="","",TEXT(INDEX(入力シート!$A$5:$A$204,AT204),"YYYYMMDD")) | E204: =IF(AT204="","",TEXT(INDEX(入力シート!$Q$5:$Q$204,AT204),"00000000")) | F204: =IF(AT204="","",14) | G204: =IF(AT204="","",1) | H204: =IF(AT204="","",1) | I204: =IF(AT204="","",3) | J204: =IF(AT204="","",1) | K204: =IF(AT204="","",INDEX(入力シート!$B$5:$B$204,AT204)) | L204: =IF(AT204="","","") | M204: =IF(AT204="","","") | N204: =IF(AT204="","",COUNTIF(入力シート!$Q$5:$Q$204,INDEX(入力シート!$Q$5:$Q$204,AT204))+1) | O204: =IF(AT204="","",99) | P204: =IF(AT204="","","") | Q204: =IF(AT204="","","") | R204: =IF(AT204="","","消費税") | S204: =IF(AT204="","",0) | T204: =IF(AT204="","","") | U204: =IF(AT204="","",0) | V204: =IF(AT204="","",0) | W204: =IF(AT204="","","") | X204: =IF(AT204="","",0) | Y204: =IF(AT204="","",0) | Z204: =IF(AT204="","",ROUNDDOWN(SUMIF(入力シート!$Q$5:$Q$204,INDEX(入力シート!$Q$5:$Q$204,AT204),入力シート!$P$5:$P$204)*IF(INDEX(入力シート!$L$5:$L$204,AT204)=13,0.1,IF(INDEX(入力シート!$L$5:$L$204,AT204)=30,0.08,0)),0)) | AA204: =IF(AT204="","","") | AB204: =IF(AT204="","",0) | AC204: =IF(AT204="","",0) | AD204: =IF(AT204="","",0) | AE204: =IF(AT204="","","") | AF204: =IF(AT204="","",0) | AG204: =IF(AT204="","",0) | AH204: =IF(AT204="","","") | AI204: =IF(AT204="","","") | AJ204: =IF(AT204="","","") | AK204: =IF(AT204="","",2) | AL204: =IF(AT204="","","") | AM204: =IF(AT204="","","") | AN204: =IF(AT204="","",INDEX(入力シート!$C$5:$C$204,AT204)) | AO204: =IF(AT204="","","") | AP204: =IF(AT204="","","") | AQ204: =IF(AT204="","","") | AT204: =IFERROR(MATCH(4,入力シート!$T$5:$T$204,0),"")
A205: =IF(AT205="","",1) | B205: =IF(AT205="","",1) | C205: =IF(AT205="","",0) | D205: =IF(AT205="","",TEXT(INDEX(入力シート!$A$5:$A$204,AT205),"YYYYMMDD")) | E205: =IF(AT205="","",TEXT(INDEX(入力シート!$Q$5:$Q$204,AT205),"00000000")) | F205: =IF(AT205="","",14) | G205: =IF(AT205="","",1) | H205: =IF(AT205="","",1) | I205: =IF(AT205="","",3) | J205: =IF(AT205="","",1) | K205: =IF(AT205="","",INDEX(入力シート!$B$5:$B$204,AT205)) | L205: =IF(AT205="","","") | M205: =IF(AT205="","","") | N205: =IF(AT205="","",COUNTIF(入力シート!$Q$5:$Q$204,INDEX(入力シート!$Q$5:$Q$204,AT205))+1) | O205: =IF(AT205="","",99) | P205: =IF(AT205="","","") | Q205: =IF(AT205="","","") | R205: =IF(AT205="","","消費税") | S205: =IF(AT205="","",0) | T205: =IF(AT205="","","") | U205: =IF(AT205="","",0) | V205: =IF(AT205="","",0) | W205: =IF(AT205="","","") | X205: =IF(AT205="","",0) | Y205: =IF(AT205="","",0) | Z205: =IF(AT205="","",ROUNDDOWN(SUMIF(入力シート!$Q$5:$Q$204,INDEX(入力シート!$Q$5:$Q$204,AT205),入力シート!$P$5:$P$204)*IF(INDEX(入力シート!$L$5:$L$204,AT205)=13,0.1,IF(INDEX(入力シート!$L$5:$L$204,AT205)=30,0.08,0)),0)) | AA205: =IF(AT205="","","") | AB205: =IF(AT205="","",0) | AC205: =IF(AT205="","",0) | AD205: =IF(AT205="","",0) | AE205: =IF(AT205="","","") | AF205: =IF(AT205="","",0) | AG205: =IF(AT205="","",0) | AH205: =IF(AT205="","","") | AI205: =IF(AT205="","","") | AJ205: =IF(AT205="","","") | AK205: =IF(AT205="","",2) | AL205: =IF(AT205="","","") | AM205: =IF(AT205="","","") | AN205: =IF(AT205="","",INDEX(入力シート!$C$5:$C$204,AT205)) | AO205: =IF(AT205="","","") | AP205: =IF(AT205="","","") | AQ205: =IF(AT205="","","") | AT205: =IFERROR(MATCH(5,入力シート!$T$5:$T$204,0),"")
A206: =IF(AT206="","",1) | B206: =IF(AT206="","",1) | C206: =IF(AT206="","",0) | D206: =IF(AT206="","",TEXT(INDEX(入力シート!$A$5:$A$204,AT206),"YYYYMMDD")) | E206: =IF(AT206="","",TEXT(INDEX(入力シート!$Q$5:$Q$204,AT206),"00000000")) | F206: =IF(AT206="","",14) | G206: =IF(AT206="","",1) | H206: =IF(AT206="","",1) | I206: =IF(AT206="","",3) | J206: =IF(AT206="","",1) | K206: =IF(AT206="","",INDEX(入力シート!$B$5:$B$204,AT206)) | L206: =IF(AT206="","","") | M206: =IF(AT206="","","") | N206: =IF(AT206="","",COUNTIF(入力シート!$Q$5:$Q$204,INDEX(入力シート!$Q$5:$Q$204,AT206))+1) | O206: =IF(AT206="","",99) | P206: =IF(AT206="","","") | Q206: =IF(AT206="","","") | R206: =IF(AT206="","","消費税") | S206: =IF(AT206="","",0) | T206: =IF(AT206="","","") | U206: =IF(AT206="","",0) | V206: =IF(AT206="","",0) | W206: =IF(AT206="","","") | X206: =IF(AT206="","",0) | Y206: =IF(AT206="","",0) | Z206: =IF(AT206="","",ROUNDDOWN(SUMIF(入力シート!$Q$5:$Q$204,INDEX(入力シート!$Q$5:$Q$204,AT206),入力シート!$P$5:$P$204)*IF(INDEX(入力シート!$L$5:$L$204,AT206)=13,0.1,IF(INDEX(入力シート!$L$5:$L$204,AT206)=30,0.08,0)),0)) | AA206: =IF(AT206="","","") | AB206: =IF(AT206="","",0) | AC206: =IF(AT206="","",0) | AD206: =IF(AT206="","",0) | AE206: =IF(AT206="","","") | AF206: =IF(AT206="","",0) | AG206: =IF(AT206="","",0) | AH206: =IF(AT206="","","") | AI206: =IF(AT206="","","") | AJ206: =IF(AT206="","","") | AK206: =IF(AT206="","",2) | AL206: =IF(AT206="","","") | AM206: =IF(AT206="","","") | AN206: =IF(AT206="","",INDEX(入力シート!$C$5:$C$204,AT206)) | AO206: =IF(AT206="","","") | AP206: =IF(AT206="","","") | AQ206: =IF(AT206="","","") | AT206: =IFERROR(MATCH(6,入力シート!$T$5:$T$204,0),"")
A207: =IF(AT207="","",1) | B207: =IF(AT207="","",1) | C207: =IF(AT207="","",0) | D207: =IF(AT207="","",TEXT(INDEX(入力シート!$A$5:$A$204,AT207),"YYYYMMDD")) | E207: =IF(AT207="","",TEXT(INDEX(入力シート!$Q$5:$Q$204,AT207),"00000000")) | F207: =IF(AT207="","",14) | G207: =IF(AT207="","",1) | H207: =IF(AT207="","",1) | I207: =IF(AT207="","",3) | J207: =IF(AT207="","",1) | K207: =IF(AT207="","",INDEX(入力シート!$B$5:$B$204,AT207)) | L207: =IF(AT207="","","") | M207: =IF(AT207="","","") | N207: =IF(AT207="","",COUNTIF(入力シート!$Q$5:$Q$204,INDEX(入力シート!$Q$5:$Q$204,AT207))+1) | O207: =IF(AT207="","",99) | P207: =IF(AT207="","","") | Q207: =IF(AT207="","","") | R207: =IF(AT207="","","消費税") | S207: =IF(AT207="","",0) | T207: =IF(AT207="","","") | U207: =IF(AT207="","",0) | V207: =IF(AT207="","",0) | W207: =IF(AT207="","","") | X207: =IF(AT207="","",0) | Y207: =IF(AT207="","",0) | Z207: =IF(AT207="","",ROUNDDOWN(SUMIF(入力シート!$Q$5:$Q$204,INDEX(入力シート!$Q$5:$Q$204,AT207),入力シート!$P$5:$P$204)*IF(INDEX(入力シート!$L$5:$L$204,AT207)=13,0.1,IF(INDEX(入力シート!$L$5:$L$204,AT207)=30,0.08,0)),0)) | AA207: =IF(AT207="","","") | AB207: =IF(AT207="","",0) | AC207: =IF(AT207="","",0) | AD207: =IF(AT207="","",0) | AE207: =IF(AT207="","","") | AF207: =IF(AT207="","",0) | AG207: =IF(AT207="","",0) | AH207: =IF(AT207="","","") | AI207: =IF(AT207="","","") | AJ207: =IF(AT207="","","") | AK207: =IF(AT207="","",2) | AL207: =IF(AT207="","","") | AM207: =IF(AT207="","","") | AN207: =IF(AT207="","",INDEX(入力シート!$C$5:$C$204,AT207)) | AO207: =IF(AT207="","","") | AP207: =IF(AT207="","","") | AQ207: =IF(AT207="","","") | AT207: =IFERROR(MATCH(7,入力シート!$T$5:$T$204,0),"")
A208: =IF(AT208="","",1) | B208: =IF(AT208="","",1) | C208: =IF(AT208="","",0) | D208: =IF(AT208="","",TEXT(INDEX(入力シート!$A$5:$A$204,AT208),"YYYYMMDD")) | E208: =IF(AT208="","",TEXT(INDEX(入力シート!$Q$5:$Q$204,AT208),"00000000")) | F208: =IF(AT208="","",14) | G208: =IF(AT208="","",1) | H208: =IF(AT208="","",1) | I208: =IF(AT208="","",3) | J208: =IF(AT208="","",1) | K208: =IF(AT208="","",INDEX(入力シート!$B$5:$B$204,AT208)) | L208: =IF(AT208="","","") | M208: =IF(AT208="","","") | N208: =IF(AT208="","",COUNTIF(入力シート!$Q$5:$Q$204,INDEX(入力シート!$Q$5:$Q$204,AT208))+1) | O208: =IF(AT208="","",99) | P208: =IF(AT208="","","") | Q208: =IF(AT208="","","") | R208: =IF(AT208="","","消費税") | S208: =IF(AT208="","",0) | T208: =IF(AT208="","","") | U208: =IF(AT208="","",0) | V208: =IF(AT208="","",0) | W208: =IF(AT208="","","") | X208: =IF(AT208="","",0) | Y208: =IF(AT208="","",0) | Z208: =IF(AT208="","",ROUNDDOWN(SUMIF(入力シート!$Q$5:$Q$204,INDEX(入力シート!$Q$5:$Q$204,AT208),入力シート!$P$5:$P$204)*IF(INDEX(入力シート!$L$5:$L$204,AT208)=13,0.1,IF(INDEX(入力シート!$L$5:$L$204,AT208)=30,0.08,0)),0)) | AA208: =IF(AT208="","","") | AB208: =IF(AT208="","",0) | AC208: =IF(AT208="","",0) | AD208: =IF(AT208="","",0) | AE208: =IF(AT208="","","") | AF208: =IF(AT208="","",0) | AG208: =IF(AT208="","",0) | AH208: =IF(AT208="","","") | AI208: =IF(AT208="","","") | AJ208: =IF(AT208="","","") | AK208: =IF(AT208="","",2) | AL208: =IF(AT208="","","") | AM208: =IF(AT208="","","") | AN208: =IF(AT208="","",INDEX(入力シート!$C$5:$C$204,AT208)) | AO208: =IF(AT208="","","") | AP208: =IF(AT208="","","") | AQ208: =IF(AT208="","","") | AT208: =IFERROR(MATCH(8,入力シート!$T$5:$T$204,0),"")
A209: =IF(AT209="","",1) | B209: =IF(AT209="","",1) | C209: =IF(AT209="","",0) | D209: =IF(AT209="","",TEXT(INDEX(入力シート!$A$5:$A$204,AT209),"YYYYMMDD")) | E209: =IF(AT209="","",TEXT(INDEX(入力シート!$Q$5:$Q$204,AT209),"00000000")) | F209: =IF(AT209="","",14) | G209: =IF(AT209="","",1) | H209: =IF(AT209="","",1) | I209: =IF(AT209="","",3) | J209: =IF(AT209="","",1) | K209: =IF(AT209="","",INDEX(入力シート!$B$5:$B$204,AT209)) | L209: =IF(AT209="","","") | M209: =IF(AT209="","","") | N209: =IF(AT209="","",COUNTIF(入力シート!$Q$5:$Q$204,INDEX(入力シート!$Q$5:$Q$204,AT209))+1) | O209: =IF(AT209="","",99) | P209: =IF(AT209="","","") | Q209: =IF(AT209="","","") | R209: =IF(AT209="","","消費税") | S209: =IF(AT209="","",0) | T209: =IF(AT209="","","") | U209: =IF(AT209="","",0) | V209: =IF(AT209="","",0) | W209: =IF(AT209="","","") | X209: =IF(AT209="","",0) | Y209: =IF(AT209="","",0) | Z209: =IF(AT209="","",ROUNDDOWN(SUMIF(入力シート!$Q$5:$Q$204,INDEX(入力シート!$Q$5:$Q$204,AT209),入力シート!$P$5:$P$204)*IF(INDEX(入力シート!$L$5:$L$204,AT209)=13,0.1,IF(INDEX(入力シート!$L$5:$L$204,AT209)=30,0.08,0)),0)) | AA209: =IF(AT209="","","") | AB209: =IF(AT209="","",0) | AC209: =IF(AT209="","",0) | AD209: =IF(AT209="","",0) | AE209: =IF(AT209="","","") | AF209: =IF(AT209="","",0) | AG209: =IF(AT209="","",0) | AH209: =IF(AT209="","","") | AI209: =IF(AT209="","","") | AJ209: =IF(AT209="","","") | AK209: =IF(AT209="","",2) | AL209: =IF(AT209="","","") | AM209: =IF(AT209="","","") | AN209: =IF(AT209="","",INDEX(入力シート!$C$5:$C$204,AT209)) | AO209: =IF(AT209="","","") | AP209: =IF(AT209="","","") | AQ209: =IF(AT209="","","") | AT209: =IFERROR(MATCH(9,入力シート!$T$5:$T$204,0),"")
A210: =IF(AT210="","",1) | B210: =IF(AT210="","",1) | C210: =IF(AT210="","",0) | D210: =IF(AT210="","",TEXT(INDEX(入力シート!$A$5:$A$204,AT210),"YYYYMMDD")) | E210: =IF(AT210="","",TEXT(INDEX(入力シート!$Q$5:$Q$204,AT210),"00000000")) | F210: =IF(AT210="","",14) | G210: =IF(AT210="","",1) | H210: =IF(AT210="","",1) | I210: =IF(AT210="","",3) | J210: =IF(AT210="","",1) | K210: =IF(AT210="","",INDEX(入力シート!$B$5:$B$204,AT210)) | L210: =IF(AT210="","","") | M210: =IF(AT210="","","") | N210: =IF(AT210="","",COUNTIF(入力シート!$Q$5:$Q$204,INDEX(入力シート!$Q$5:$Q$204,AT210))+1) | O210: =IF(AT210="","",99) | P210: =IF(AT210="","","") | Q210: =IF(AT210="","","") | R210: =IF(AT210="","","消費税") | S210: =IF(AT210="","",0) | T210: =IF(AT210="","","") | U210: =IF(AT210="","",0) | V210: =IF(AT210="","",0) | W210: =IF(AT210="","","") | X210: =IF(AT210="","",0) | Y210: =IF(AT210="","",0) | Z210: =IF(AT210="","",ROUNDDOWN(SUMIF(入力シート!$Q$5:$Q$204,INDEX(入力シート!$Q$5:$Q$204,AT210),入力シート!$P$5:$P$204)*IF(INDEX(入力シート!$L$5:$L$204,AT210)=13,0.1,IF(INDEX(入力シート!$L$5:$L$204,AT210)=30,0.08,0)),0)) | AA210: =IF(AT210="","","") | AB210: =IF(AT210="","",0) | AC210: =IF(AT210="","",0) | AD210: =IF(AT210="","",0) | AE210: =IF(AT210="","","") | AF210: =IF(AT210="","",0) | AG210: =IF(AT210="","",0) | AH210: =IF(AT210="","","") | AI210: =IF(AT210="","","") | AJ210: =IF(AT210="","","") | AK210: =IF(AT210="","",2) | AL210: =IF(AT210="","","") | AM210: =IF(AT210="","","") | AN210: =IF(AT210="","",INDEX(入力シート!$C$5:$C$204,AT210)) | AO210: =IF(AT210="","","") | AP210: =IF(AT210="","","") | AQ210: =IF(AT210="","","") | AT210: =IFERROR(MATCH(10,入力シート!$T$5:$T$204,0),"")
A211: =IF(AT211="","",1) | B211: =IF(AT211="","",1) | C211: =IF(AT211="","",0) | D211: =IF(AT211="","",TEXT(INDEX(入力シート!$A$5:$A$204,AT211),"YYYYMMDD")) | E211: =IF(AT211="","",TEXT(INDEX(入力シート!$Q$5:$Q$204,AT211),"00000000")) | F211: =IF(AT211="","",14) | G211: =IF(AT211="","",1) | H211: =IF(AT211="","",1) | I211: =IF(AT211="","",3) | J211: =IF(AT211="","",1) | K211: =IF(AT211="","",INDEX(入力シート!$B$5:$B$204,AT211)) | L211: =IF(AT211="","","") | M211: =IF(AT211="","","") | N211: =IF(AT211="","",COUNTIF(入力シート!$Q$5:$Q$204,INDEX(入力シート!$Q$5:$Q$204,AT211))+1) | O211: =IF(AT211="","",99) | P211: =IF(AT211="","","") | Q211: =IF(AT211="","","") | R211: =IF(AT211="","","消費税") | S211: =IF(AT211="","",0) | T211: =IF(AT211="","","") | U211: =IF(AT211="","",0) | V211: =IF(AT211="","",0) | W211: =IF(AT211="","","") | X211: =IF(AT211="","",0) | Y211: =IF(AT211="","",0) | Z211: =IF(AT211="","",ROUNDDOWN(SUMIF(入力シート!$Q$5:$Q$204,INDEX(入力シート!$Q$5:$Q$204,AT211),入力シート!$P$5:$P$204)*IF(INDEX(入力シート!$L$5:$L$204,AT211)=13,0.1,IF(INDEX(入力シート!$L$5:$L$204,AT211)=30,0.08,0)),0)) | AA211: =IF(AT211="","","") | AB211: =IF(AT211="","",0) | AC211: =IF(AT211="","",0) | AD211: =IF(AT211="","",0) | AE211: =IF(AT211="","","") | AF211: =IF(AT211="","",0) | AG211: =IF(AT211="","",0) | AH211: =IF(AT211="","","") | AI211: =IF(AT211="","","") | AJ211: =IF(AT211="","","") | AK211: =IF(AT211="","",2) | AL211: =IF(AT211="","","") | AM211: =IF(AT211="","","") | AN211: =IF(AT211="","",INDEX(入力シート!$C$5:$C$204,AT211)) | AO211: =IF(AT211="","","") | AP211: =IF(AT211="","","") | AQ211: =IF(AT211="","","") | AT211: =IFERROR(MATCH(11,入力シート!$T$5:$T$204,0),"")
A212: =IF(AT212="","",1) | B212: =IF(AT212="","",1) | C212: =IF(AT212="","",0) | D212: =IF(AT212="","",TEXT(INDEX(入力シート!$A$5:$A$204,AT212),"YYYYMMDD")) | E212: =IF(AT212="","",TEXT(INDEX(入力シート!$Q$5:$Q$204,AT212),"00000000")) | F212: =IF(AT212="","",14) | G212: =IF(AT212="","",1) | H212: =IF(AT212="","",1) | I212: =IF(AT212="","",3) | J212: =IF(AT212="","",1) | K212: =IF(AT212="","",INDEX(入力シート!$B$5:$B$204,AT212)) | L212: =IF(AT212="","","") | M212: =IF(AT212="","","") | N212: =IF(AT212="","",COUNTIF(入力シート!$Q$5:$Q$204,INDEX(入力シート!$Q$5:$Q$204,AT212))+1) | O212: =IF(AT212="","",99) | P212: =IF(AT212="","","") | Q212: =IF(AT212="","","") | R212: =IF(AT212="","","消費税") | S212: =IF(AT212="","",0) | T212: =IF(AT212="","","") | U212: =IF(AT212="","",0) | V212: =IF(AT212="","",0) | W212: =IF(AT212="","","") | X212: =IF(AT212="","",0) | Y212: =IF(AT212="","",0) | Z212: =IF(AT212="","",ROUNDDOWN(SUMIF(入力シート!$Q$5:$Q$204,INDEX(入力シート!$Q$5:$Q$204,AT212),入力シート!$P$5:$P$204)*IF(INDEX(入力シート!$L$5:$L$204,AT212)=13,0.1,IF(INDEX(入力シート!$L$5:$L$204,AT212)=30,0.08,0)),0)) | AA212: =IF(AT212="","","") | AB212: =IF(AT212="","",0) | AC212: =IF(AT212="","",0) | AD212: =IF(AT212="","",0) | AE212: =IF(AT212="","","") | AF212: =IF(AT212="","",0) | AG212: =IF(AT212="","",0) | AH212: =IF(AT212="","","") | AI212: =IF(AT212="","","") | AJ212: =IF(AT212="","","") | AK212: =IF(AT212="","",2) | AL212: =IF(AT212="","","") | AM212: =IF(AT212="","","") | AN212: =IF(AT212="","",INDEX(入力シート!$C$5:$C$204,AT212)) | AO212: =IF(AT212="","","") | AP212: =IF(AT212="","","") | AQ212: =IF(AT212="","","") | AT212: =IFERROR(MATCH(12,入力シート!$T$5:$T$204,0),"")
A213: =IF(AT213="","",1) | B213: =IF(AT213="","",1) | C213: =IF(AT213="","",0) | D213: =IF(AT213="","",TEXT(INDEX(入力シート!$A$5:$A$204,AT213),"YYYYMMDD")) | E213: =IF(AT213="","",TEXT(INDEX(入力シート!$Q$5:$Q$204,AT213),"00000000")) | F213: =IF(AT213="","",14) | G213: =IF(AT213="","",1) | H213: =IF(AT213="","",1) | I213: =IF(AT213="","",3) | J213: =IF(AT213="","",1) | K213: =IF(AT213="","",INDEX(入力シート!$B$5:$B$204,AT213)) | L213: =IF(AT213="","","") | M213: =IF(AT213="","","") | N213: =IF(AT213="","",COUNTIF(入力シート!$Q$5:$Q$204,INDEX(入力シート!$Q$5:$Q$204,AT213))+1) | O213: =IF(AT213="","",99) | P213: =IF(AT213="","","") | Q213: =IF(AT213="","","") | R213: =IF(AT213="","","消費税") | S213: =IF(AT213="","",0) | T213: =IF(AT213="","","") | U213: =IF(AT213="","",0) | V213: =IF(AT213="","",0) | W213: =IF(AT213="","","") | X213: =IF(AT213="","",0) | Y213: =IF(AT213="","",0) | Z213: =IF(AT213="","",ROUNDDOWN(SUMIF(入力シート!$Q$5:$Q$204,INDEX(入力シート!$Q$5:$Q$204,AT213),入力シート!$P$5:$P$204)*IF(INDEX(入力シート!$L$5:$L$204,AT213)=13,0.1,IF(INDEX(入力シート!$L$5:$L$204,AT213)=30,0.08,0)),0)) | AA213: =IF(AT213="","","") | AB213: =IF(AT213="","",0) | AC213: =IF(AT213="","",0) | AD213: =IF(AT213="","",0) | AE213: =IF(AT213="","","") | AF213: =IF(AT213="","",0) | AG213: =IF(AT213="","",0) | AH213: =IF(AT213="","","") | AI213: =IF(AT213="","","") | AJ213: =IF(AT213="","","") | AK213: =IF(AT213="","",2) | AL213: =IF(AT213="","","") | AM213: =IF(AT213="","","") | AN213: =IF(AT213="","",INDEX(入力シート!$C$5:$C$204,AT213)) | AO213: =IF(AT213="","","") | AP213: =IF(AT213="","","") | AQ213: =IF(AT213="","","") | AT213: =IFERROR(MATCH(13,入力シート!$T$5:$T$204,0),"")
A214: =IF(AT214="","",1) | B214: =IF(AT214="","",1) | C214: =IF(AT214="","",0) | D214: =IF(AT214="","",TEXT(INDEX(入力シート!$A$5:$A$204,AT214),"YYYYMMDD")) | E214: =IF(AT214="","",TEXT(INDEX(入力シート!$Q$5:$Q$204,AT214),"00000000")) | F214: =IF(AT214="","",14) | G214: =IF(AT214="","",1) | H214: =IF(AT214="","",1) | I214: =IF(AT214="","",3) | J214: =IF(AT214="","",1) | K214: =IF(AT214="","",INDEX(入力シート!$B$5:$B$204,AT214)) | L214: =IF(AT214="","","") | M214: =IF(AT214="","","") | N214: =IF(AT214="","",COUNTIF(入力シート!$Q$5:$Q$204,INDEX(入力シート!$Q$5:$Q$204,AT214))+1) | O214: =IF(AT214="","",99) | P214: =IF(AT214="","","") | Q214: =IF(AT214="","","") | R214: =IF(AT214="","","消費税") | S214: =IF(AT214="","",0) | T214: =IF(AT214="","","") | U214: =IF(AT214="","",0) | V214: =IF(AT214="","",0) | W214: =IF(AT214="","","") | X214: =IF(AT214="","",0) | Y214: =IF(AT214="","",0) | Z214: =IF(AT214="","",ROUNDDOWN(SUMIF(入力シート!$Q$5:$Q$204,INDEX(入力シート!$Q$5:$Q$204,AT214),入力シート!$P$5:$P$204)*IF(INDEX(入力シート!$L$5:$L$204,AT214)=13,0.1,IF(INDEX(入力シート!$L$5:$L$204,AT214)=30,0.08,0)),0)) | AA214: =IF(AT214="","","") | AB214: =IF(AT214="","",0) | AC214: =IF(AT214="","",0) | AD214: =IF(AT214="","",0) | AE214: =IF(AT214="","","") | AF214: =IF(AT214="","",0) | AG214: =IF(AT214="","",0) | AH214: =IF(AT214="","","") | AI214: =IF(AT214="","","") | AJ214: =IF(AT214="","","") | AK214: =IF(AT214="","",2) | AL214: =IF(AT214="","","") | AM214: =IF(AT214="","","") | AN214: =IF(AT214="","",INDEX(入力シート!$C$5:$C$204,AT214)) | AO214: =IF(AT214="","","") | AP214: =IF(AT214="","","") | AQ214: =IF(AT214="","","") | AT214: =IFERROR(MATCH(14,入力シート!$T$5:$T$204,0),"")
A215: =IF(AT215="","",1) | B215: =IF(AT215="","",1) | C215: =IF(AT215="","",0) | D215: =IF(AT215="","",TEXT(INDEX(入力シート!$A$5:$A$204,AT215),"YYYYMMDD")) | E215: =IF(AT215="","",TEXT(INDEX(入力シート!$Q$5:$Q$204,AT215),"00000000")) | F215: =IF(AT215="","",14) | G215: =IF(AT215="","",1) | H215: =IF(AT215="","",1) | I215: =IF(AT215="","",3) | J215: =IF(AT215="","",1) | K215: =IF(AT215="","",INDEX(入力シート!$B$5:$B$204,AT215)) | L215: =IF(AT215="","","") | M215: =IF(AT215="","","") | N215: =IF(AT215="","",COUNTIF(入力シート!$Q$5:$Q$204,INDEX(入力シート!$Q$5:$Q$204,AT215))+1) | O215: =IF(AT215="","",99) | P215: =IF(AT215="","","") | Q215: =IF(AT215="","","") | R215: =IF(AT215="","","消費税") | S215: =IF(AT215="","",0) | T215: =IF(AT215="","","") | U215: =IF(AT215="","",0) | V215: =IF(AT215="","",0) | W215: =IF(AT215="","","") | X215: =IF(AT215="","",0) | Y215: =IF(AT215="","",0) | Z215: =IF(AT215="","",ROUNDDOWN(SUMIF(入力シート!$Q$5:$Q$204,INDEX(入力シート!$Q$5:$Q$204,AT215),入力シート!$P$5:$P$204)*IF(INDEX(入力シート!$L$5:$L$204,AT215)=13,0.1,IF(INDEX(入力シート!$L$5:$L$204,AT215)=30,0.08,0)),0)) | AA215: =IF(AT215="","","") | AB215: =IF(AT215="","",0) | AC215: =IF(AT215="","",0) | AD215: =IF(AT215="","",0) | AE215: =IF(AT215="","","") | AF215: =IF(AT215="","",0) | AG215: =IF(AT215="","",0) | AH215: =IF(AT215="","","") | AI215: =IF(AT215="","","") | AJ215: =IF(AT215="","","") | AK215: =IF(AT215="","",2) | AL215: =IF(AT215="","","") | AM215: =IF(AT215="","","") | AN215: =IF(AT215="","",INDEX(入力シート!$C$5:$C$204,AT215)) | AO215: =IF(AT215="","","") | AP215: =IF(AT215="","","") | AQ215: =IF(AT215="","","") | AT215: =IFERROR(MATCH(15,入力シート!$T$5:$T$204,0),"")
